Workbook

Sheet Summary
A1: 01/01/2024 - 31/05/2024 | B1: Period Quantity | C1: Number of Months | D1: Quantity per Month | E1: Fee per Ton | F1: Fee Payable
A2: Liquibox | B2: ='Liqui Box - Usage 2024'!B4 -> 69988 | C2: 5 | D2: =B2/C2 -> 13997.6 | E2: 750 | F2: =Table15[[#This Row],[Period Quantity]]*Table15[[#This Row],[Fee per Ton]]/1000 -> 52491
A3: MTech | B3: ='MTech - Usage 2024'!B4 -> 46 | C3: 5 | D3: =B3/C3 -> 9.2 | E3: 750 | F3: =Table15[[#This Row],[Period Quantity]]*Table15[[#This Row],[Fee per Ton]]/1000 -> 34.5
A4: Didget | B4: 718 | C4: 5 | D4: =B4/C4 -> 143.6 | E4: 750 | F4: =Table15[[#This Row],[Period Quantity]]*Table15[[#This Row],[Fee per Ton]]/1000 -> 538.5
B5: =SUM(B2:B4) -> 70752 | D5: =SUM(D2:D4) -> 14150.4 | F5: =SUM(F2:F4) -> 53064
A7: 01/01/2023 - 31/12/2023 | B7: Period Quantity | C7: Number of Months | D7: Quantity per Month | E7: Fee per Ton | F7: Fee Payable
A8: Liquibox | B8: ='Liqui Box - Usage 2023'!B4 -> 222835.5 | C8: 12 | D8: =B8/C8 -> 18569.625 | E8: 750 | F8: =Table1[[#This Row],[Period Quantity]]*Table1[[#This Row],[Fee per Ton]]/1000 -> 167126.62
A9: MTech | B9: ='MTech - Usage 2023'!B4 -> -3228.5 | C9: 12 | D9: =B9/C9 -> -269.04167 | E9: 750 | F9: =Table1[[#This Row],[Period Quantity]]*Table1[[#This Row],[Fee per Ton]]/1000 -> -2421.375
A10: Didget | B10: 2123 | C10: 12 | D10: =B10/C10 -> 176.91667 | E10: 750 | F10: =Table1[[#This Row],[Period Quantity]]*Table1[[#This Row],[Fee per Ton]]/1000 -> 1592.25
B11: =SUM(B8:B10) -> 221730 | D11: =SUM(D8:D10) -> 18477.5 | F11: =SUM(F8:F10) -> 166297.5
A14: 01/01/2022 - 31/12/2022 | B14: Period Quantity | C14: Number of Months | D14: Quantity per Month | E14: Fee per Ton | F14: Fee Payable
A15: Liquibox | B15: ='Liqui Box - Usage 2022'!B4 -> 192386.92 | C15: 12 | D15: =B15/C15 -> 16032.243 | E15: 750 | F15: =Table14[[#This Row],[Period Quantity]]*Table14[[#This Row],[Fee per Ton]]/1000 -> 144290.19
A16: MTech | B16: ='MTech - Usage 2022'!B4 -> 84720 | C16: 12 | D16: =B16/C16 -> 7060 | E16: 750 | F16: =Table14[[#This Row],[Period Quantity]]*Table14[[#This Row],[Fee per Ton]]/1000 -> 63540
A17: Didget | B17: 1793 | C17: 12 | D17: =B17/C17 -> 149.41667 | E17: 750 | F17: =Table14[[#This Row],[Period Quantity]]*Table14[[#This Row],[Fee per Ton]]/1000 -> 1344.75
B18: =SUM(B15:B17) -> 278899.92 | D18: =SUM(D15:D17) -> 23241.66 | F18: =SUM(F15:F17) -> 209174.94
B20: =SUM(B5,B11,B18) -> 571381.92
A21: Kangopak Internal Inititive | B21: Period Cost | C21: Number of Months | D21: Column3 | E21: Cost per Month | F21: Total Cost
A22: Waste Control - 2022 | B22: 103167.8 | C22: 12 | E22: =Table13[[#This Row],[Period Cost]]/Table13[[#This Row],[Number of Months]] -> 8597.3167 | F22: =Table13[[#This Row],[Period Cost]] -> 103167.8
A23: Waste Control - 2023 | B23: 103689.48 | C23: 12 | E23: =Table13[[#This Row],[Period Cost]]/Table13[[#This Row],[Number of Months]] -> 8640.79 | F23: =Table13[[#This Row],[Period Cost]] -> 103689.48
A24: Waste Control - 2024 | B24: 56859.606 | C24: 5 | E24: =Table13[[#This Row],[Period Cost]]/Table13[[#This Row],[Number of Months]] -> 11371.921 | F24: =Table13[[#This Row],[Period Cost]] -> 56859.606
B25: =SUM(B22:B24) -> 263716.89 | F25: =SUM(F22:F24) -> 263716.89
A28: Total Material Bought | B28: =SUM('Liqui Box - Usage 2024'!B1,'Liqui Box - Usage 2023'!B1,'MTech - Usage 2024'!B1,'MTech - Usage 2023'!B1) -> 486745

Sheet Liqui Box - Usage 2024
A1: Total Sourced - 2024 | B1: =SUM(B34,B39,B42,B52,B55,B59,B71,B82,B90,B94,B159,B162,B167,B189) -> 101936.5
A2: EPR Charged Quantity | B2: 0
A3: Export Material - 2024 | B3: =-B189 -> -31948.5
A4: Billable Quantity - | B4: =SUM(B1:B3) -> 69988
A6: Prepared by: Kangopak
A7: Purchase Items per Supplier : 01-01-2024 to 31-05-2024
B8: Doc No | C8: Date | D8: Qty | E8: Unit Cost | F8: Total
A9: Supplier : LIQ001 - Liqui-Box (Pty) Ltd
A10: Item : 2000/000 - Cost of Sales
B11: PNA22905 | C11: 09-02-2024 | F11: 4.05
A12: Total for Item : 2000/000 | D12: 4.05
A13: Item : 3560/000 - Rounding
B14: PNA23023 | C14: 19-03-2024 | F14: 0.005
B15: PNA23050 | C15: 19-04-2024 | F15: 0.003
B16: PNA23079 | C16: 29-04-2024 | F16: -0.001
B17: PNA23081 | C17: 06-05-2024 | F17: -0.001
B18: PNA23083 | C18: 06-05-2024 | F18: 0.002
B19: PNA23089 | C19: 03-04-2024 | F19: 0.01
B20: PNA23090 | C20: 03-04-2024 | F20: -0.005
B21: PNA23107 | C21: 06-05-2024 | F21: -0.004
B22: PNA23108 | C22: 14-05-2024 | F22: 0.005
B23: PNA23109 | C23: 20-05-2024 | F23: 0.005
B24: PNA23129 | C24: 30-05-2024 | F24: 0.005
B25: PNA23154 | C25: 23-05-2024 | F25: 0.009
B26: PCA10552 | C26: 25-04-2024 | F26: -0.004
A27: Total for Item : 3560/000 | D27: 0.029
A28: Item : 4350/000 - Repairs & Maintenance
B29: PNA23051 | C29: 22-04-2024 | F29: -0.001
B30: PNA23052 | C30: 22-04-2024 | F30: 0.002
A31: Total for Item : 4350/000 | D31: 0.001
A32: Item : ALS52 - Anlam 52mic Parent Reel 1290mm
B33: PNA23129 | C33: 30-05-2024 | D33: 510 | E33: 90.62 | F33: 46216.2
A34: Total for Item : ALS52 | B34: 510 | C34: 90.62 | D34: 46216.2
A35: Item : ALS85 - ALS 85mic Enabled 1290mm Parent Reel
B36: PNA22846 | C36: 29-01-2024 | D36: 1183 | E36: 90.93 | F36: 107570.19
B37: PNA22903 | C37: 07-02-2024 | D37: 1228 | E37: 90.93 | F37: 111662.04
B38: PNA23107 | C38: 06-05-2024 | D38: 1752 | E38: 90.93 | F38: 159309.36
A39: Total for Item : ALS85 | B39: 4163 | C39: 90.93 | D39: 378541.59
A40: Item : ANLAM110 - ALS110 Unenabled Parent Reel 1290mm
B41: PNA23079 | C41: 29-04-2024 | D41: 2131 | E41: 74.92 | F41: 159654.52
...

Sheet Liqui Box - Usage 2023
A1: Total Sourced - 2023 | B1: =SUM(B17,B30,B36,B52,B61,B75,B82,B95,B100,B108,B139,B143,B150,B161,B176,B284,B287,B290,B295,B320,B323) -> 286703
A2: EPR Charged Quantity | B2: 0
A3: Export Material - 2023 | B3: =-B320 -> -63867.5
A4: Billable Quantity - | B4: =SUM(B1:B3) -> 222835.5
A6: Prepared by: Kangopak
A7: Purchase Items per Supplier : 01-01-2023 to 31-12-2023
B8: Doc No | C8: Date | D8: Qty | E8: Unit Cost | F8: Total
A9: Supplier : LIQ001 - Liqui-Box (Pty) Ltd
A10: Item : 2000/000 - Cost of Sales
B11: PNA22344 | C11: 07-06-2023 | F11: 362.25
B12: PNA22544 | C12: 11-07-2023 | F12: 762.7
B13: PNA22545 | C13: 11-07-2023 | F13: 361.81
A14: Total for Item : 2000/000 | D14: 1486.76
A15: Item : ALS85 - ALS 85mic Enabled 1290mm Parent Reel
B16: PNA22797 | C16: 08-12-2023 | D16: 1491 | E16: 90.93 | F16: 135576.63
A17: Total for Item : ALS85 | B17: 1491 | C17: 90.93 | D17: 135576.63
A18: Item : ANLAM110 - ALS110 Unenabled Parent Reel 1290mm
B19: PNA22075 | C19: 26-01-2023 | D19: 1123 | E19: 74.92 | F19: 84135.16
B20: PNA22108 | C20: 16-02-2023 | D20: 537.5 | E20: 74.92 | F20: 40269.5
B21: PNA22189 | C21: 27-03-2023 | D21: 1557 | E21: 74.92 | F21: 116650.44
B22: PNA22241 | C22: 17-04-2023 | D22: 1167 | E22: 74.92 | F22: 87431.64
B23: PNA22244 | C23: 18-04-2023 | D23: 2742 | E23: 74.92 | F23: 205430.64
B24: PNA22350 | C24: 19-06-2023 | D24: 1362 | E24: 74.92 | F24: 102041.04
B25: PNA22403 | C25: 17-07-2023 | D25: 1166 | E25: 74.92 | F25: 87356.72
B26: PNA22436 | C26: 08-08-2023 | D26: 601 | E26: 74.92 | F26: 45026.92
B27: PNA22597 | C27: 12-10-2023 | D27: 1775 | E27: 74.92 | F27: 132983
B28: PNA22742 | C28: 17-11-2023 | D28: 1256 | E28: 74.92 | F28: 94099.52
B29: PCA10517 | C29: 11-08-2023 | D29: -218.5 | E29: 74.92 | F29: -16370.02
A30: Total for Item : ANLAM110 | B30: 13068 | C30: 74.92 | D30: 979054.56
A31: Item : ANLAM62 - ALS62 Unenabled Parent Reel 1290mm
B32: PNA22264 | C32: 10-05-2023 | D32: 292 | E32: 78.27 | F32: 22854.84
B33: PNA22345 | C33: 07-06-2023 | D33: 226 | E33: 78.27 | F33: 17689.02
B34: PNA22655 | C34: 20-10-2023 | D34: 442 | E34: 78.27 | F34: 34595.34
B35: PNA22743 | C35: 17-11-2023 | D35: 211 | E35: 78.27 | F35: 16514.97
A36: Total for Item : ANLAM62 | B36: 1171 | C36: 78.27 | D36: 91654.17
A37: Item : CBP110 - CBP110 Unenabled Parent Reel 1290mm
B38: PNA22095 | C38: 03-02-2023 | D38: 585 | E38: 78.86 | F38: 46133.1
B39: PNA22096 | C39: 04-02-2023 | D39: 328 | E39: 78.86 | F39: 25866.08
B40: PNA22097 | C40: 06-02-2023 | D40: 1240 | E40: 78.86 | F40: 97786.4
B41: PNA22098 | C41: 08-02-2023 | D41: 554 | E41: 78.86 | F41: 43688.44
...

Sheet Liqui Box - Usage 2022
A1: Total Sourced - 2022 | B1: =SUM(B23,B48,B75,B96,B102,B109,B105,B125,B160,B164,B167,B173,B188,B191,B194,B197,B201,B209,B216,B212,B219,B225,B229,B236) -> 213080.42
A2: EPR Charged Quantity | B2: 0
A3: Export Material - PVNS160 - 2022 | B3: =-B209 -> -20693.5
A4: Billable Quantity - | B4: =SUM(B1:B3) -> 192386.92
A6: Prepared by: Kangopak
A7: Purchase Items per Supplier : 01-01-2022 to 31-12-2022
B8: Doc No | C8: Date | D8: Qty | E8: Unit Cost | F8: Total
A9: Supplier : LIQ001 - Liqui-Box (Pty) Ltd
A10: Item : 4350/000 - Repairs & Maintenance
B11: PNA21363 | C11: 25-02-2022 | F11: 2873
A12: Total for Item : 4350/000 | D12: 2873
A13: Item : ANLAM110 - ALS110 Unenabled Parent Reel 1290mm
B14: PNA21325 | C14: 23-02-2022 | D14: 717.5 | E14: 71.33 | F14: 51179.275
B15: PNA21407 | C15: 25-03-2022 | D15: 1568 | E15: 71.33 | F15: 111845.44
B16: PNA21477 | C16: 20-04-2022 | D16: 4638 | E16: 71.33 | F16: 330828.54
B17: PNA21756 | C17: 26-08-2022 | D17: 1122 | E17: 74.92 | F17: 84060.24
B18: PNA21805 | C18: 19-09-2022 | D18: 1232 | E18: 74.92 | F18: 92301.44
B19: PNA21846 | C19: 18-10-2022 | D19: 1123.5 | E19: 74.92 | F19: 84172.62
B20: PNA21965 | C20: 17-11-2022 | D20: 1081.5 | E20: 74.92 | F20: 81025.98
B21: PNA21972 | C21: 05-12-2022 | D21: 331 | E21: 74.92 | F21: 24798.52
B22: PNA21974 | C22: 06-12-2022 | D22: 534.5 | E22: 74.92 | F22: 40044.74
A23: Total for Item : ANLAM110 | B23: 12348 | C23: 72.907094 | D23: 900256.8
A24: Item : ANLAM62 - ALS62 Unenabled Parent Reel 1290mm
B25: PNA21478 | C25: 21-04-2022 | D25: 519.5 | E25: 75.07 | F25: 38998.865
B26: PNA21642 | C26: 21-07-2022 | D26: 597 | E26: 78.27 | F26: 46727.19
A27: Total for Item : ANLAM62 | B27: 1116.5 | C27: 76.781061 | D27: 85726.055
A28: Item : CARTSTOCK - Stock Carton
B29: PNA21919 | C29: 11-11-2022 | D29: 846 | E29: 12.37 | F29: 10465.02
A30: Total for Item : CARTSTOCK | B30: 846 | C30: 12.37 | D30: 10465.02
A31: Item : CBP110 - CBP110 Unenabled Parent Reel 1290mm
B32: PNA21225 | C32: 17-01-2022 | D32: 1825 | E32: 68.25 | F32: 124556.25
B33: PNA21270 | C33: 20-01-2022 | D33: 540 | E33: 68.25 | F33: 36855
B34: PNA21390 | C34: 08-03-2022 | D34: 2447 | E34: 75.43 | F34: 184577.21
B35: PNA21508 | C35: 25-04-2022 | D35: 1475 | E35: 78.86 | F35: 116318.5
B36: PNA21582 | C36: 20-06-2022 | D36: 2993 | E36: 78.86 | F36: 236027.98
B37: PNA21754 | C37: 25-08-2022 | D37: 2194 | E37: 78.86 | F37: 173018.84
B38: PNA21755 | C38: 26-08-2022 | D38: 534 | E38: 78.86 | F38: 42111.24
B39: PNA21762 | C39: 15-09-2022 | D39: 1353 | E39: 78.86 | F39: 106697.58
B40: PNA21764 | C40: 15-08-2022 | D40: 451.5 | E40: 78.86 | F40: 35605.29
B41: PNA21868 | C41: 25-10-2022 | D41: 3396.5 | E41: 78.86 | F41: 267847.99
...

Sheet MTech - Usage 2024
A1: Total Sourced - 2024 | B1: =SUM(B31,B38,B46,B90,B99,B107,B112,B115,B118,B121,B124,B127,B130,B133,B136) -> 37273
A2: EPR Charged Quantity | B2: =-B83 -> -37227
A3: Export Material - 2024 | B3: =-B209 -> 0
A4: Billable Quantity - | B4: =SUM(B1:B3) -> 46
A6: Prepared by: Kangopak
A7: Purchase Items per Supplier : 01-01-2024 to 31-05-2024
B8: Doc No | C8: Date | D8: Qty | E8: Unit Cost | F8: Total
A9: Supplier : MTE001 - Mtech SA (Pty) Ltd
A10: Item : 3560/000 - Rounding
B11: PNA23020 | C11: 26-03-2024 | F11: -0.003
B12: PNA23021 | C12: 28-03-2024 | F12: 0.024
B13: PNA23030 | C13: 05-04-2024 | F13: -0.004
B14: PNA23049 | C14: 10-04-2024 | F14: 0.002
B15: PNA23071 | C15: 29-04-2024 | F15: 0.007
B16: PNA23072 | C16: 29-04-2024 | F16: 0.007
B17: PNA23073 | C17: 29-04-2024 | F17: 0.019
B18: PNA23074 | C18: 02-05-2024 | F18: 0.006
B19: PNA23075 | C19: 06-05-2024 | F19: -0.021
B20: PNA23078 | C20: 10-05-2024 | F20: 0.023
B21: PNA23093 | C21: 13-05-2024 | F21: -0.011
B22: PCA10551 | C22: 10-04-2024 | F22: -0.002
A23: Total for Item : 3560/000 | D23: 0.047
A24: Item : CNC001 - Crown National 110mic Front Pan Rev Prnt
B25: PNA22840 | C25: 22-01-2024 | D25: 1017 | E25: 90.08 | F25: 91611.36
B26: PNA22872 | C26: 09-02-2024 | D26: 2562 | E26: 90.08 | F26: 230784.96
B27: PNA22877 | C27: 12-01-2024 | D27: 2413 | E27: 90.08 | F27: 217363.04
B28: PNA22950 | C28: 12-02-2024 | D28: 2413 | E28: 90.08 | F28: 217363.04
B29: PNA22960 | C29: 01-03-2024 | D29: 1622 | E29: 90.08 | F29: 146109.76
B30: PCA10545 | C30: 12-01-2024 | D30: -2413 | E30: 90.08 | F30: -217363.04
A31: Total for Item : CNC001 | B31: 7614 | C31: 90.08 | D31: 685869.12
A32: Item : CNG001 - Crown National 110mic Gussets
B33: PNA22840 | C33: 22-01-2024 | D33: 97 | E33: 75.31 | F33: 7305.07
B34: PNA22873 | C34: 09-02-2024 | D34: 943 | E34: 75.31 | F34: 71017.33
B35: PNA22879 | C35: 12-02-2024 | D35: 1078 | E35: 75.31 | F35: 81184.18
B36: PNA22962 | C36: 01-03-2024 | D36: 174 | E36: 75.31 | F36: 13103.94
B37: PNA22966 | C37: 04-03-2024 | D37: 360 | E37: 75.31 | F37: 27111.6
A38: Total for Item : CNG001 | B38: 2652 | C38: 75.31 | D38: 199722.12
A39: Item : CNP001 - Crown National 110mic Back Pan Rev Print
B40: PNA22840 | C40: 22-01-2024 | D40: 590 | E40: 93.58 | F40: 55212.2
B41: PNA22874 | C41: 09-02-2024 | D41: 2197 | E41: 93.58 | F41: 205595.26
...

Sheet MTech - Usage 2023
A1: Total Sourced - 2023 | B1: =SUM(B21,B30,B42,B53,B65,B72,B147,B150,B153,B179,B204,B217,B224) -> 60832.5
A2: EPR Charged Quantity | B2: =-B144 -> -64061
A3: Export Material - 2023 | B3: 0
A4: Billable Quantity - | B4: =SUM(B1:B3) -> -3228.5
A6: Prepared by: Kangopak
A7: Purchase Items per Supplier : 01-01-2023 to 31-12-2023
B8: Doc No | C8: Date | D8: Qty | E8: Unit Cost | F8: Total
A9: Supplier : MTE001 - Mtech SA (Pty) Ltd
A10: Item : CNC001 - Crown National 110mic Front Pan Rev Prnt
B11: PNA22533 | C11: 08-09-2023 | D11: 108 | E11: 91.09 | F11: 9837.72
B12: PNA22534 | C12: 11-09-2023 | D12: 985 | E12: 91.09 | F12: 89723.65
B13: PNA22535 | C13: 13-09-2023 | D13: 134 | E13: 91.09 | F13: 12206.06
B14: PNA22542 | C14: 15-09-2023 | D14: 961 | E14: 91.09 | F14: 87537.49
B15: PNA22570 | C15: 22-09-2023 | D15: 138 | E15: 91.09 | F15: 12570.42
B16: PNA22572 | C16: 27-09-2023 | D16: 530 | E16: 91.09 | F16: 48277.7
B17: PNA22728 | C17: 28-11-2023 | D17: 1073 | E17: 90.08 | F17: 96655.84
B18: PNA22791 | C18: 07-12-2023 | D18: 807 | E18: 90.08 | F18: 72694.56
B19: PNA22792 | C19: 08-12-2023 | D19: 539 | E19: 90.08 | F19: 48553.12
B20: PNA22793 | C20: 13-12-2023 | D20: 1475 | E20: 90.08 | F20: 132868
A21: Total for Item : CNC001 | B21: 6750 | C21: 90.507342 | D21: 610924.56
A22: Item : CNG001 - Crown National 110mic Gussets
B23: PNA22533 | C23: 08-09-2023 | D23: 81 | E23: 76 | F23: 6156
B24: PNA22534 | C24: 11-09-2023 | D24: 63 | E24: 76 | F24: 4788
B25: PNA22536 | C25: 13-09-2023 | D25: 804 | E25: 76 | F25: 61104
B26: PNA22727 | C26: 28-11-2023 | D26: 380 | E26: 75.31 | F26: 28617.8
B27: PNA22791 | C27: 07-12-2023 | D27: 291 | E27: 75.31 | F27: 21915.21
B28: PNA22792 | C28: 08-12-2023 | D28: 195 | E28: 75.31 | F28: 14685.45
B29: PNA22793 | C29: 13-12-2023 | D29: 525 | E29: 75.31 | F29: 39537.75
A30: Total for Item : CNG001 | B30: 2339 | C30: 75.589658 | D30: 176804.21
A31: Item : CNP001 - Crown National 110mic Back Pan Rev Print
B32: PNA22533 | C32: 08-09-2023 | D32: 119 | E32: 39.95 | F32: 4754.05
B33: PNA22534 | C33: 11-09-2023 | D33: 1079 | E33: 39.95 | F33: 43106.05
B34: PNA22535 | C34: 13-09-2023 | D34: 135 | E34: 39.95 | F34: 5393.25
B35: PNA22542 | C35: 15-09-2023 | D35: 926 | E35: 39.95 | F35: 36993.7
B36: PNA22570 | C36: 22-09-2023 | D36: 135 | E36: 39.95 | F36: 5393.25
B37: PNA22572 | C37: 27-09-2023 | D37: 524 | E37: 39.95 | F37: 20933.8
B38: PNA22749 | C38: 28-11-2023 | D38: 1139 | E38: 93.58 | F38: 106587.62
B39: PNA22791 | C39: 07-12-2023 | D39: 887 | E39: 93.58 | F39: 83005.46
B40: PNA22792 | C40: 08-12-2023 | D40: 588 | E40: 93.58 | F40: 55025.04
B41: PNA22793 | C41: 13-12-2023 | D41: 1625 | E41: 93.58 | F41: 152067.5
...

Sheet MTech - Usage 2022
A1: Total Sourced - 2022 | B1: =SUM(B13,B16,B24,B33,B37,B45,B53,B62,B82,B86,B89,B92,B95,B98,B108,B120,B138,B141,B146,B151,B155) -> 70539
A2: EPR Charged Quantity | B2: =B79 -> 14181
A3: Export Material - 2022 | B3: 0
A4: Billable Quantity - | B4: =SUM(B1:B3) -> 84720
A6: Prepared by: Kangopak
A7: Purchase Items per Supplier : 01-01-2022 to 31-12-2022
B8: Doc No | C8: Date | D8: Qty | E8: Unit Cost | F8: Total
A9: Supplier : MTE001 - Mtech SA (Pty) Ltd
A10: Item : CLOV007 - Clover Print Reels Cheddar Elite 100mic
B11: PNA21615 | C11: 04-07-2022 | D11: 557 | E11: 109.63 | F11: 61063.91
B12: PNA21616 | C12: 05-07-2022 | D12: 508 | E12: 109.63 | F12: 55692.04
A13: Total for Item : CLOV007 | B13: 1065 | C13: 109.63 | D13: 116755.95
A14: Item : CLOV008 - Clover Print Reels Gouda Elite 100mic
B15: PNA21615 | C15: 04-07-2022 | D15: 1002 | E15: 109.63 | F15: 109849.26
A16: Total for Item : CLOV008 | B16: 1002 | C16: 109.63 | D16: 109849.26
A17: Item : CNC001 - Crown National 110mic Front Pan Rev Prnt
B18: PNA21510 | C18: 06-05-2022 | D18: 255 | E18: 78.05 | F18: 19902.75
B19: PNA21523 | C19: 11-05-2022 | D19: 1255 | E19: 78.05 | F19: 97952.75
B20: PNA21560 | C20: 18-05-2022 | D20: 4091 | E20: 78.05 | F20: 319302.55
B21: PNA21561 | C21: 16-05-2022 | D21: 4871 | E21: 78.05 | F21: 380181.55
B22: PNA21562 | C22: 11-05-2022 | D22: 1133 | E22: 78.05 | F22: 88430.65
B23: PCA10463 | C23: 11-05-2022 | D23: -1255 | E23: 78.05 | F23: -97952.75
A24: Total for Item : CNC001 | B24: 10350 | C24: 78.05 | D24: 807817.5
A25: Item : CNP001 - Crown National 110mic Back Pan Rev Print
B26: PNA21510 | C26: 06-05-2022 | D26: 270 | E26: 79.89 | F26: 21570.3
B27: PNA21523 | C27: 11-05-2022 | D27: 1133 | E27: 79.89 | F27: 90515.37
B28: PNA21524 | C28: 16-05-2022 | D28: 1344 | E28: 79.89 | F28: 107372.16
B29: PNA21558 | C29: 19-05-2022 | D29: 2721 | E29: 79.89 | F29: 217380.69
B30: PNA21559 | C30: 18-05-2022 | D30: 3769 | E30: 79.89 | F30: 301105.41
B31: PNA21562 | C31: 11-05-2022 | D31: 1255 | E31: 79.89 | F31: 100261.95
B32: PCA10463 | C32: 11-05-2022 | D32: -1133 | E32: 79.89 | F32: -90515.37
A33: Total for Item : CNP001 | B33: 9359 | C33: 79.89 | D33: 747690.51
A34: Item : CPU132 - 12mic Clear PET // 130mic Clear LLDPE
B35: PNA21297 | C35: 08-02-2022 | D35: 4092 | E35: 62.25 | F35: 254727
B36: PNA21314 | C36: 08-02-2022 | D36: 7249 | E36: 62.25 | F36: 451250.25
A37: Total for Item : CPU132 | B37: 11341 | C37: 62.25 | D37: 705977.25
A38: Item : DSB001 - D Spic Bck Pan 110x210x66mm 430mm 110mic
B39: PNA21652 | C39: 27-07-2022 | D39: 504 | E39: 101.87 | F39: 51342.48
B40: PNA21653 | C40: 28-07-2022 | D40: 635 | E40: 101.87 | F40: 64687.45
B41: PNA21730 | C41: 29-08-2022 | D41: 1087 | E41: 91.63 | F41: 99601.81
...
